Workbook

Sheet Perfil de Riesgo
B2: Evalua tu Perfil de Riesgo
B4: Cada persona tiene una actitud y una capacidad diferentes para asumir riesgos con su dinero. Completa la evaluación para conocer el tuyo. Para cada pregunta selecciona del menu desplegable la respuesta más adecuada.
B6: PREGUNTAS SOBRE TU CAPACIDAD PARA ASUMIR RIESGOS | C6: Puntos
B7: =+B55 -> 1. ¿Cuándo necesitarás retirar el 50% o más de este dinero?
B8: Más de 25 años | C8: =VLOOKUP(B8,B56:C60,2,FALSE) -> 40
B9: =+B61 -> 2. Describe tu situación laboral/ingresos:
B10: Funcionario o ingresos pasivos recurrentes | C10: =VLOOKUP(B10,B62:C65,2,FALSE) -> 12
B11: =+B66 -> 3. Fuera de esta inversión, ¿cuántos meses de gastos tienes en liquidez?
B12: Más de 12 meses | C12: =VLOOKUP(B12,B67:C70,2,FALSE) -> 16
B13: =+B71 -> 4. ¿Qué % de tu patrimonio líquido total representa esta inversión?
B14: Menos del 20% | C14: =VLOOKUP(B14,B72:C76,2,FALSE) -> 20
B15: =+B77 -> 5. ¿Tienes deudas significativas?
B16: No, sin deudas | C16: =VLOOKUP(B16,B78:C81,2,FALSE) -> 12
B17: Sí, solo hipoteca razonable (<30% ingresos)
B18: Puntuación TOTAL CAPACIDAD PARA ASUMIR RIESGOS | C18: =SUM(C8:C16) -> 100
B20: PREGUNTAS SOBRE TU ACTITUD HACIA EL RIESGO
B21: =+B83 -> 6. ¿Has vivido una caída del mercado >20% con dinero invertido?
B22: Sí, y compré más aprovechando | C22: =VLOOKUP(B22,B84:C88,2,FALSE) -> 20
B23: =+B89 -> 7. Tienes 100.000€ invertidos. En 6 meses, el mercado cae 40% y tu cartera vale 60.000€. ¿Qué haces?
B24: Aprovecho para aportar más | C24: =VLOOKUP(B24,B90:C94,2,FALSE) -> 25
B25: =+B95 -> 8. ¿Cada cuánto revisas el valor de tu cartera?
B26: Anualmente o menos | C26: =VLOOKUP(B26,B96:C100,2,FALSE) -> 12
B27: =+B101 -> 9. Tu cartera lleva 2 años rindiendo -5% anual mientras el plazo fijo da +2%. ¿Cómo te sientes?
B28: Tranquilo, son solo 2 años en un horizonte largo | C28: =VLOOKUP(B28,B102:C105,2,FALSE) -> 18
B29: =+B106 -> 10. ¿Qué priorizas en tu inversión?
B30: Máxima rentabilidad esperada, la volatilidad no me afecta emocionalmente | C30: =VLOOKUP(B30,B107:C110,2,FALSE) -> 25
B32: Puntuación TOTAL TOLERANCIA AL RIESGO | C32: =SUM(C22:C30) -> 100
B34: Tu perfil de riesgo es: | C34: =+MIN(C18,C32) -> 100
B36: =IF(C34<=20, CONCATENATE(B41,CHAR(10),B42), IF(C34<=40, CONCATENATE(B43,B44),IF(C34<=60,CONCATENATE(B45,B46),IF(C34<=80,CONCATENATE(B47,B48), IF(C34>80,CONCATENATE(B49,B50), "Completa el formulario"))))) -> Agresivo (81-100 puntos):Un inversor agresivo busca el máximo crecimiento del capital. Este inversor está dispuesto a tolerar fluctuaciones en los rendimientos que son similares a los observados en los mercados de renta variable, puede requerir un pequeño ingreso y está preparado para invertir por un periodo mínimo de diez años. Una meta de rendimiento adecuada para este perfil podría ser el IPC más un 5 a 6% durante diez años. Objetivo de Rendimiento: 9-10
B40: Perfiles
B41: Conservador (0-20 puntos):
B42: Un inversor conservador busca preservar su capital de inversión y es en gran medida adverso al riesgo. Este tipo de inversor requiere consistencia y baja variabilidad en los rendimientos, así como acceso al capital dentro de los primeros tres años. Una meta de rendimiento adecuada para este perfil podría ser el índice de inflación (IPC) más un 1 a 2% durante un periodo móvil de tres años. Objetivo de Rendimiento: 1-2
B43: Moderadamente Conservador (21-40 puntos):
B44: Un inversor moderadamente conservador también busca preservar su capital de inversión mientras logra un crecimiento estable. Este inversor requiere consistencia en los rendimientos y puede necesitar ingresos regulares y acceso al capital dentro de un periodo de tres años. Una meta de rendimiento adecuada para este perfil podría ser el IPC más un 2 a 3% en un periodo de tres años. Objetivo de Rendimiento: 3-4
B45: Moderado (41-60 puntos):
B46: Un inversor moderado prefiere el crecimiento de capital sobre la preservación del capital. Está dispuesto a tolerar fluctuaciones moderadas en los rendimientos de la inversión, puede necesitar ingresos regulares y está preparado para invertir por un periodo mínimo de cinco años. Una meta de rendimiento adecuada para este perfil podría ser el IPC más un 3 a 4% durante cinco años. Objetivo de Rendimiento: 5-6
B47: Moderadamente Agresivo (61-80 puntos):
B48: Un inversor moderadamente agresivo busca el crecimiento del capital y está dispuesto a tolerar fluctuaciones en los rendimientos similares a los que se ven en los mercados de renta variable. Puede requerir un pequeño ingreso y está preparado para invertir por un periodo mínimo de siete años. Una meta de rendimiento adecuada para este perfil podría ser el IPC más un 4 a 5% durante siete años. Objetivo de Rendimiento: 7-8
B49: Agresivo (81-100 puntos):
B50: Un inversor agresivo busca el máximo crecimiento del capital. Este inversor está dispuesto a tolerar fluctuaciones en los rendimientos que son similares a los observados en los mercados de renta variable, puede requerir un pequeño ingreso y está preparado para invertir por un periodo mínimo de diez años. Una meta de rendimiento adecuada para este perfil podría ser el IPC más un 5 a 6% durante diez años. Objetivo de Rendimiento: 9-10
...

Sheet Fondos de Inversión Indexada
C7: Fondos de Inversión Indexada
C9: Nombre | D9: ISIN | E9: TER | F9: Gestora | G9: Mercado | H9: Categoría
C10: Vanguard U.S. 500 Stock Index Fund Investor EUR Accumulation | D10: IE0032126645 | E10: 0.001 | F10: Vanguard | G10: USA | H10: Renta Variable
C11: Fidelity S&P 500 Index Fund P-ACC-EUR | D11: IE00BYX5MX6 | E11: 0.0006 | F11: Fidelity | G11: USA | H11: Renta Variable
C12: Vanguard European Stock Index Fund Investor EUR Accumulation | D12: IE0007987690 | E12: 0.0012 | F12: Vanguard | G12: Europa | H12: Renta Variable
C13: Fidelity MSCI Europe Index Fund EUR P Acc | D13: IE00BYX5MD61 | E13: 0.001 | F13: Fidelity | G13: Europa | H13: Renta Variable
C14: Vanguard Japan Stock Index Inv EUR Acc | D14: IE0007281425 | E14: 0.0016 | F14: Vanguard | G14: Japón | H14: Renta Variable
C15: Fidelity MSCI Japan Index Fund EUR P Acc | D15: IE00BYX5N771 | E15: 0.001 | F15: Fidelity | G15: Japón | H15: Renta Variable
C16: Vanguard Pacific ex-Japan Stock Index Fund EUR Acc | D16: IE0007201266 | E16: 0.0016 | F16: Vanguard | G16: Asia ExJapón | H16: Renta Variable
C18: iShares Emerging Markets Index Fund (IE) D Acc EUR | D18: IE00BYWYCC39 | E18: 0.002 | F18: Blackrock | G18: Emergentes | H18: Renta Variable
C19: Vanguard Emerging Markets Stock Index Fund EUR Acc | D19: IE0031786696 | E19: 0.0023 | F19: Vanguard | G19: Emergentes | H19: Renta Variable
C20: iShares Emerging Markets Index Fund (IE) Acc EUR clase S | D20: IE000QAZP7L2 | E20: 0.0016 | F20: Blackrock | G20: Emergentes | H20: Renta Variable | I20: MyInvestor
C22: Vanguard Global Small-Cap Index Fund Investor EUR Accumulation | D22: IE00B42W3S00 | E22: 0.003 | F22: Vanguard | G22: Small Caps | H22: Renta Variable
C23: Vanguard Global Stock Index Fund EUR Acc | D23: IE00B03HD191 | E23: 0.0018 | F23: Vanguard | G23: Global Desarrollado | H23: Renta Variable
C24: Fidelity MSCI World Index Fund P-ACC-EUR | D24: IE00BYX5NX33 | E24: 0.0012 | F24: Fidelity | G24: Global Desarrollado | H24: Renta Variable | I24: MyInvestor
C25: iShares Dev Wld Idx (IE) S Acc EUR | D25: IE000ZYRH0Q7 | E25: 0.0006 | F25: Blackrock | G25: Global Desarrollado | H25: Renta Variable | I25: MyInvestor
C26: iShares Developed World ESG Screened Index Fund (IE) D Acc EUR | D26: IE000N51F726 | E26: 0.0015 | F26: Blackrock | G26: Global Desarrollado | H26: Renta Variable | I26: MyInvestor | J26: ESG
C30: Nombre | D30: ISIN | E30: TER | F30: Gestora | G30: Mercado | H30: Plazo | I30: Duración | J30: Categoría
C31: Vanguard 20+ Year Euro Treasury Index Fund | D31: IE00B246KL88 | E31: 0.0016 | F31: Vanguard | G31: Europa | H31: Largo Plazo | I31: 19.9 | J31: Pública
C32: Vanguard US Government Bond Index Fund EUR Hedged | D32: IE0007471471 | E32: 0.0012 | F32: Vanguard | G32: USA | H32: Medio Plazo | I32: 5.79 | J32: Pública
C33: Vanguard Global Short Term Bond Ix Inv EURH Acc | D33: IE00BH65QK91 | E33: 0.0015 | F33: Vanguard | G33: Global | H33: Corto Plazo | I33: 2.69 | J33: Mixto
C34: Vanguard Eurozone Inflation-Linked Bond Idx Inv EUR Acc | D34: IE00B04GQQ17 | E34: 0.0012 | F34: Vanguard | G34: Europa | H34: TIPS/Medio Plazo | I34: 7.11 | J34: Pública
C35: Vanguard Euro Government Bond Index Fund EUR Acc | D35: IE0007472990 | E35: 0.0012 | F35: Vanguard | G35: Europa | H35: Medio Plazo | I35: 7 | J35: Pública
C36: iShares Ultra High Quality Euro Government Bond Index Fund (IE) Institutional Acc EUR | D36: IE00B4XCK338 | E36: 0.0013 | F36: Blackrock | G36: Europa | H36: Medio Plazo | I36: 7.58 | J36: Pública
C39: iShares Euro Investment Grade Corporate Bond Index Fund (IE) D Acc EUR | D39: IE00BDRK7J14 | E39: 0.0012 | F39: Blackrock | G39: Global | H39: Corto Plazo | I39: 4.42 | J39: Corporativa
C40: Vanguard Global Corporate Bond Index Fund EUR Hedged Accumulation | D40: IE00BDFB5N63 | E40: 0.0018 | F40: Vanguard | G40: Global | H40: Medio Plazo | I40: 6 | J40: Corporativa
C41: Vanguard Emerging Markets Bond Fund Investor EUR Hedged Accumulation | D41: IE00BKLWXS37 | E41: 0.0061 | F41: Vanguard | G41: Emergentes | H41: Medio Plazo | I41: 6 | J41: High Yield
C42: iShares Emerging Markets Government Bond Index Fund (LU) A2 EUR Hedged | D42: LU1373035580 | E42: 0.0052 | F42: Blackrock | G42: Emergentes | H42: Medio Plazo | I42: 6.66 | J42: High Yield

Sheet ETFs
C6: ETFs
B8: Ticket JustEtf | C8: Nombre | D8: ISIN | E8: TER | F8: Gestora | G8: Mercado | H8: Categoría
A9: Geográfica | B9: VUAA | C9: Vanguard S&P 500 UCITS ETF (USD) Accumulating | D9: IE00BFMXXD54 | E9: 0.0007 | F9: Vanguard | G9: USA | H9: Renta Variable
B10: EUNK | C10: iShares Core MSCI Europe UCITS ETF EUR (Acc) | D10: IE00B4K48X80 | E10: 0.0012 | F10: Blackrock | G10: Europa | H10: Renta Variable | I10: MyInvestor
B11: VJPA | C11: Vanguard FTSE Japan UCITS ETF Accumulating | D11: IE00BFMXYX26 | E11: 0.0015 | F11: Vanguard | G11: Japón | H11: Renta Variable
B12: SXR1 | C12: iShares Core MSCI Pacific ex Japan UCITS ETF (Acc) | D12: IE00B52MJY50 | E12: 0.002 | F12: Blackrock | G12: Asia ExJapón | H12: Renta Variable | I12: MyInvestor
B13: IS3N | C13: iShares Core MSCI Emerging Markets IMI UCITS ETF (Acc) | D13: IE00BKM4GZ66 | E13: 0.0023 | F13: Blackrock | G13: Emergentes | H13: Renta Variable | I13: MyInvestor
B14: ZPRS | C14: SPDR MSCI World Small Cap UCITS ETF | D14: IE00BCBJG560 | E14: 0.0045 | F14: SPDR | G14: Small Caps | H14: Renta Variable | I14: MyInvestor
A16: Global | B16: EUNL | C16: iShares Core MSCI World UCITS ETF USD (Acc) | D16: IE00B4L5Y983 | E16: 0.002 | F16: Blackrock | G16: Global Desarrollado | H16: Renta Variable | I16: MyInvestor
B17: SPPW | C17: SPDR MSCI World UCITS ETF | D17: IE00BFY0GT14 | E17: 0.0012 | F17: SPDR | G17: Global Desarrollado | H17: Renta Variable
B18: SPYY | C18: SPDR MSCI ACWI UCITS ETF | D18: IE00B44Z5B48 | E18: 0.0012 | F18: SPDR | G18: Global con Emergetes | H18: Renta Variable
B19: IUSQ | C19: iShares MSCI ACWI UCITS ETF USD (Acc) | D19: IE00B6R52259 | E19: 0.002 | F19: Blackrock | G19: Global con Emergetes | H19: Renta Variable | I19: MyInvestor
A22: Sectorial | B22: XDWS | C22: Xtrackers MSCI World Consumer Staples UCITS ETF 1C | D22: IE00BM67HN09 | E22: 0.0025 | F22: Xtrackers | G22: Consumo básico | H22: Renta Variable | I22: MyInvestor
B23: XDWH | C23: Xtrackers MSCI World Health Care UCITS ETF 1C | D23: IE00BM67HK77 | E23: 0.0025 | F23: Xtrackers | G23: Salud | H23: Renta Variable | I23: MyInvestor
B24: LYPE | C24: Amundi MSCI World Health Care UCITS ETF EUR Acc | D24: LU0533033238 | E24: 0.003 | F24: Amundi/Lyxor | G24: Salud | H24: Renta Variable | I24: MyInvestor
B25: XDWT | C25: Xtrackers MSCI World Information Technology UCITS ETF 1C | D25: IE00BM67HT60 | E25: 0.0025 | F25: Xtrackers | G25: Tecnología | H25: Renta Variable | I25: MyInvestor
B26: XDW0 | C26: Xtrackers MSCI World Energy UCITS ETF 1C | D26: IE00BM67HM91 | E26: 0.0025 | F26: Xtrackers | G26: Energía | H26: Renta Variable | I26: MyInvestor
B27: A4H5 | C27: Amundi Index FTSE EPRA NAREIT Global UCITS ETF DR | D27: LU1437018838 | E27: 0.0024 | F27: Amundi | G27: Real Estate | H27: Renta Variable | I27: MyInvestor
B28: XDWU | C28: Xtrackers MSCI World Utilities UCITS ETF 1C | D28: IE00BM67HQ30 | E28: 0.0025 | F28: Xtrackers | G28: Utilities | H28: Renta Variable | I28: MyInvestor
B29: H4Z7 | C29: HSBC FTSE EPRA NAREIT Developed UCITS ETF USD (Acc) | D29: IE000G6GSP88 | E29: 0.0024 | F29: HSBC | G29: Real Estate | H29: Renta Variable
B33: Ticket JustEtf | C33: Nombre | D33: ISIN | E33: TER | F33: Gestora | G33: Mercado | H33: Plazo | I33: Duración | J33: Categoría
A34: Deuda Pública | B34: DBZB | C34: Xtrackers II Global Government Bond UCITS ETF 1C EUR Hedged | D34: LU0378818131 | E34: 0.0025 | F34: Xtrackers | G34: Global | H34: Mixto | I34: 6.84 | J34: Publica | K34: MyInvestor
B35: LMTH | C35: Amundi Euro Government Bond 25+Y UCITS ETF Acc | D35: LU1686832194 | E35: 0.0007 | F35: Amundi | G35: Europa | H35: Largo Plazo | I35: 22 | J35: Publica
B36: LYQ6 | C36: Amundi Euro Government Bond 10-15Y UCITS ETF Acc | D36: LU1650489385 | E36: 0.0015 | F36: Amundi | G36: Europa | H36: Largo Plazo | I36: 10.25 | J36: Publica | K36: MyInvestor
B37: LYXD | C37: Amundi Euro Government Bond 7-10Y UCITS ETF Acc | D37: LU1287023185 | E37: 0.0015 | F37: Amundi | G37: Europa | H37: Medio Plazo | I37: 7.31 | J37: Publica | K37: MyInvestor
B38: X57E | C38: Xtrackers Eurozone Government Bond 5-7 UCITS ETF 1C | D38: LU0290357176 | E38: 0.0015 | F38: Xtrackers | G38: Europa | H38: Medio Plazo | I38: 5.6 | J38: Publica | K38: MyInvestor
B39: SXRP | C39: iShares Euro Government Bond 3-7yr UCITS ETF (Acc) | D39: IE00B3VTML14 | E39: 0.0015 | F39: Blackrock | G39: Europa | H39: Medio Plazo | I39: 4.44 | J39: Publica | K39: MyInvestor
B40: LYQ3 | C40: Amundi Euro Government Bond 3-5Y UCITS ETF Acc | D40: LU1650488494 | E40: 0.0015 | F40: Amundi | G40: Europa | H40: Corto Plazo | I40: 3.73 | J40: Publica | K40: MyInvestor
B41: LYQ2 | C41: Amundi Euro Government Bond 1-3Y UCITS ETF Acc | D41: LU1650487413 | E41: 0.0015 | F41: Amundi | G41: Europa | H41: Corto Plazo | I41: 1.31 | J41: Publica | K41: MyInvestor
B42: 7USH | C42: Amundi US Treasury Bond 7-10Y UCITS ETF EUR Hedged Acc | D42: LU1407888137 | E42: 0.0006 | F42: Amundi | G42: USA | H42: Medio Plazo | I42: 7.24 | J42: Publica
B43: 2B7S | C43: iShares USD Treasury Bond 1-3yr UCITS ETF EUR Hedged (Acc) | D43: IE00BDFK1573 | E43: 0.001 | F43: Blackrock | G43: USA | H43: Corto Plazo | I43: 1.88 | J43: Publica | K43: MyInvestor
B44: VDTE | C44: Vanguard USD Treasury Bond UCITS ETF EUR Hedged Accumulating | D44: IE00BMX0B631 | E44: 0.0012 | F44: Vanguard | G44: USA | H44: Mixto | I44: 6.01 | J44: Publica | K44: MyInvestor
A46: Deuda Corporativa | B46: VECA | C46: Vanguard EUR Corporate Bond UCITS ETF Accumulating | D46: IE00BGYWT403 | E46: 0.0009 | F46: Vanguard | G46: Global | H46: Mixto | I46: 4.48 | J46: Corporativa | K46: MyInvestor
B47: D5BG | C47: Xtrackers II EUR Corporate Bond UCITS ETF 1C | D47: LU0478205379 | E47: 0.0012 | F47: Xtrackers | G47: Europa | H47: Mixto | I47: 4.51 | J47: Corporativa | K47: MyInvestor
B48: XZE5 | C48: Xtrackers II EUR Corporate Bond Short Duration SRI PAB UCITS ETF 1C | D48: LU2178481649 | E48: 0.0016 | F48: Xtrackers | G48: Europa | H48: Corto Plazo | I48: 2.38 | J48: Corporativa | K48: MyInvestor
B49: A4H8 | C49: Amundi Index Euro Corporate SRI UCITS ETF DR (C) | D49: LU1437018168 | E49: 0.0014 | F49: Amundi | G49: Europa | H49: Mixto | I49: 4.44 | J49: Corporativa | K49: MyInvestor
B50: UEF8 | C50: UBS ETF (LU) Bloomberg US Liquid Corporates 1-5 Year UCITS ETF (hedged to EUR) A-acc | D50: LU1048315243 | E50: 0.0019 | F50: UBS | G50: USA | H50: Corto Plazo | I50: 3.3 | J50: Corporativa | K50: MyInvestor
A52: High Yield | B52: SXRI | C52: iShares EUR High Yield Corporate Bond UCITS ETF EUR (Acc) | D52: IE00BF3N7094 | E52: 0.005 | F52: Blackrock | G52: Europa | H52: Mixto | I52: 2.32 | J52: High Yield
B53: XHYA | C53: Xtrackers EUR High Yield Corporate Bond UCITS ETF 1C | D53: LU1109943388 | E53: 0.002 | F53: Xtrackers | G53: Europa | H53: Mixto | I53: 2.28 | J53: High Yield
B54: AYE2 | C54: iShares EUR High Yield Corporate Bond ESG UCITS ETF EUR (Acc) | D54: IE00BJK55C48 | E54: 0.0025 | F54: Blackrock | G54: Europa | H54: Mixto | I54: 3.35 | J54: High Yield | K54: MyInvestor
...

Sheet Control Cartera K Geográfica FI
F2: Solo las celdas con este color se pueden modificar poniendo el capital actual en cada región o tipo de activo
F4: Capital Actual | G4: 10000 | I4: *El capital que suma todas las posiciones de la cartera
F5: Aportación | G5: 0 | I5: * Aportación que quieres hacer a la cartera
B6: RIESGO | C6: 6 | F6: Capital Final | G6: =+G4+G5 -> 10000 | I6: * Capital final que quedará después de realizar la aportación
B9: Cartera | C9: Pesos | F9: Renta Variable | G9: =+H9*$G$6 -> 5500 | H9: =+C11 -> 0.55
B11: Renta Variable | C11: =+LOOKUP($C$6,'Pesos Cartera K Geográfica'!$C$4:$L$4,'Pesos Cartera K Geográfica'!C18:L18) -> 0.55 | G11: Región | H11: Valor € Actual | I11: Peso Objetivo | J11: Peso Actual | K11: Valor € Objetivo | L11: Comprar/Vender
B12: Global | C12: =+LOOKUP($C$6,'Pesos Cartera K Geográfica'!$C$4:$L$4,'Pesos Cartera K Geográfica'!C30:L30) -> 0.5115 | F12: Fidelity MSCI World Index Fund P-ACC-EUR | G12: GLOBAL | H12: 0 | I12: =C12 -> 0.5115 | J12: =+H12/$G$6 -> 0 | K12: =+I12*$G$6 -> 5115 | L12: =+K12-H12 -> 5115
B13: Emergente | C13: =+LOOKUP($C$6,'Pesos Cartera K Geográfica'!$C$4:$L$4,'Pesos Cartera K Geográfica'!C31:L31) -> 0.0385 | F13: Vanguard Emerging Markets Stock Index Fund EUR Acc | G13: Emergente | H13: 0 | I13: =C13 -> 0.0385 | J13: =+H13/$G$6 -> 0 | K13: =+I13*$G$6 -> 385 | L13: =+K13-H13 -> 385
F14: Total Renta Variable | H14: =SUM(H11:H13) -> 0 | I14: =SUM(I12:I13) -> 0.55 | J14: =SUM(J12:J13) -> 0 | K14: =SUM(K12:K13) -> 5500 | L14: =SUM(L12:L13) -> 5500
B18: Renta Fija | C18: =+LOOKUP($C$6,'Pesos Cartera K Sectorial'!$C$10:$L$10,'Pesos Cartera K Sectorial'!C25:L25) -> 0.25 | G18: Renta Fija | H18: =+I18*$G$6 -> 2500 | I18: =+C18 -> 0.25
G20: Tipo | H20: Valor € Actual | I20: Peso Objetivo | J20: Peso Actual | K20: Valor € Objetivo | L20: Comprar/Vender
B21: Gubernamental | C21: =+LOOKUP($C$6,'Pesos Cartera K Sectorial'!$C$10:$L$10,'Pesos Cartera K Sectorial'!C53:L53) -> 0.25 | E21: Duración Mod. | G21: Gubernamental | H21: =SUM(H22:H24) -> 0 | I21: =SUM(I22:I24) -> 0 | J21: =SUM(J22:J24) -> 0 | K21: =+I21*$G$6 -> 0 | L21: =+K21-H21 -> 0
B22: Largo Plazo | E22: 19.9 | F22: Vanguard 20+ Year Euro Treasury Index Fund | G22: Largo Plazo | I22: =+C22 | J22: =+H22/$G$6 -> 0 | K22: =+I22*$G$6 -> 0 | L22: =+K22-H22 -> 0
B23: Medio Plazo | E23: 7.33 | F23: iShares Ultra High Quality Euro Government Bond Index Fund (IE) Institutional Acc EUR | G23: Medio Plazo | H23: 0 | I23: =+C23 | J23: =+H23/$G$6 -> 0 | K23: =+I23*$G$6 -> 0 | L23: =+K23-H23 -> 0
B24: Corto Plazo | G24: Corto Plazo | I24: =+C24 | J24: =+H24/$G$6 -> 0 | K24: =+I24*$G$6 -> 0 | L24: =+K24-H24 -> 0
B26: Corporativa | C26: =+LOOKUP($C$6,'Pesos Cartera K Sectorial'!$C$10:$L$10,'Pesos Cartera K Sectorial'!C54:L54) -> 0 | E26: 2.69 | G26: Corporativa | I26: =+C26 -> 0 | J26: =+H26/$G$6 -> 0 | K26: =+I26*$G$6 -> 0 | L26: =+K26-H26 -> 0
B27: High Yield | C27: =+LOOKUP($C$6,'Pesos Cartera K Sectorial'!$C$10:$L$10,'Pesos Cartera K Sectorial'!C55:L55) -> 0 | E27: 6 | F27: Vanguard Emerging Markets Bond Fund Investor EUR Hedged Accumulation | G27: High Yield | H27: 0 | I27: =+C27 -> 0 | J27: =+H27/$G$6 -> 0 | K27: =+I27*$G$6 -> 0 | L27: =+K27-H27 -> 0
E28: =+(E22*C22+E23*C23+E24*C24+E26*C26+E27*C27)/C18 -> 0 | F28: Total Renta Fija | H28: =+H21+H26+H27 -> 0 | I28: =+I18 -> 0.25 | J28: =+H28/$G$6 -> 0 | K28: =+I28*$G$6 -> 2500 | L28: =+K28-H28 -> 2500
B30: Oro | C30: =+LOOKUP($C$6,'Pesos Cartera K Sectorial'!$C$10:$L$10,'Pesos Cartera K Sectorial'!C26:L26) -> 0.2 | G30: Oro | H30: =+I30*$G$6 -> 2000 | I30: =+C30 -> 0.2
G32: Activo | H32: Valor € Actual | I32: Peso Objetivo | J32: Peso Actual | K32: Valor € Objetivo | L32: Comprar/Vender
F33: Total Oro | G33: Oro | H33: 0 | I33: =+I30 -> 0.2 | J33: =+H33/$G$6 -> 0 | K33: =+I33*$G$6 -> 2000 | L33: =+K33-H33 -> 2000
G35: TOTAL | H35: =+H33+H28+H14 -> 0 | K35: =+K33+K28+K14 -> 10000 | L35: =+K35-H35 -> 10000
F41: Fondo Monetario que sirve para acumular liquidez
F42: ISIN | G42: Fondo | H42: Activo | I42: Valor € Actual | J42: TER
F43: FR0000447823 | G43: AXA Trésor Court Terme C | H43: Monetario | I43: 0 | J43: 0.0006

Sheet  Control Cartera K Geográfica E
F2: Solo las celdas con este color se pueden modificar poniendo el capital actual en cada región o tipo de activo
F4: Capital Actual | G4: 12000 | I4: *El capital que suma todas las posiciones de la cartera
F5: Aportación | G5: -5000 | I5: * Aportación que quieres hacer a la cartera
B6: RIESGO | C6: 8 | F6: Capital Final | G6: =+G4+G5 -> 7000 | I6: * Capital final que quedará después de realizar la aportación
B9: Cartera | C9: Pesos | F9: Renta Variable | G9: =+H9*$G$6 -> 4900 | H9: =+C11 -> 0.7
B11: Renta Variable | C11: =+LOOKUP($C$6,'Pesos Cartera K Geográfica'!$C$4:$L$4,'Pesos Cartera K Geográfica'!C18:L18) -> 0.7 | G11: Región | H11: Valor € Actual | I11: Peso Objetivo | J11: Peso Actual | K11: Valor € Objetivo | L11: Comprar/Vender
B12: Global | C12: =+LOOKUP($C$6,'Pesos Cartera K Geográfica'!$C$4:$L$4,'Pesos Cartera K Geográfica'!C30:L30) -> 0.651 | F12: SPDR MSCI ACWI UCITS ETF | G12: GLOBAL | H12: 9000 | I12: =C11 -> 0.7 | J12: =+H12/$G$6 -> 1.2857143 | K12: =+I12*$G$6 -> 4900 | L12: =+K12-H12 -> -4100
B13: Emergente | C13: =+LOOKUP($C$6,'Pesos Cartera K Geográfica'!$C$4:$L$4,'Pesos Cartera K Geográfica'!C31:L31) -> 0.049 | F13: Total Renta Variable | H13: =SUM(H11:H12) -> 9000 | I13: =SUM(I12) -> 0.7 | J13: =SUM(J12) -> 1.2857143 | K13: =SUM(K12) -> 4900 | L13: =SUM(L12) -> -4100
B17: Renta Fija | C17: =+LOOKUP($C$6,'Pesos Cartera K Sectorial'!$C$10:$L$10,'Pesos Cartera K Sectorial'!C25:L25) -> 0.1 | G17: Renta Fija | H17: =+I17*$G$6 -> 700 | I17: =+C17 -> 0.1
G19: Tipo | H19: Valor € Actual | I19: Peso Objetivo | J19: Peso Actual | K19: Valor € Objetivo | L19: Comprar/Vender
B20: Gubernamental | C20: =+LOOKUP($C$6,'Pesos Cartera K Sectorial'!$C$10:$L$10,'Pesos Cartera K Sectorial'!C53:L53) -> 0.1 | E20: Duración Mod. | G20: Gubernamental | H20: =SUM(H21:H23) -> 500 | I20: =SUM(I21:I23) -> 0.1 | J20: =SUM(J21:J23) -> 0.071428571 | K20: =+I20*$G$6 -> 700 | L20: =+K20-H20 -> 200
B21: Largo Plazo | C21: 0.07 | E21: 10.12 | F21: Amundi Euro Government Bond 10-15Y UCITS ETF Acc | G21: Largo Plazo | H21: 500 | I21: =+C21 -> 0.07 | J21: =+H21/$G$6 -> 0.071428571 | K21: =+I21*$G$6 -> 490 | L21: =+K21-H21 -> -10
B22: Medio Plazo | C22: 0.03 | E22: 6.84 | F22: Xtrackers II Global Government Bond UCITS ETF 1C EUR Hedged | G22: Medio Plazo | H22: 0 | I22: =+C22 -> 0.03 | J22: =+H22/$G$6 -> 0 | K22: =+I22*$G$6 -> 210 | L22: =+K22-H22 -> 210
B23: Corto Plazo | C23: 0 | E23: 1.88 | F23: iShares USD Treasury Bond 1-3yr UCITS ETF EUR Hedged (Acc) | G23: Corto Plazo | I23: =+C23 -> 0 | J23: =+H23/$G$6 -> 0 | K23: =+I23*$G$6 -> 0 | L23: =+K23-H23 -> 0
B25: Corporativa | C25: =+LOOKUP($C$6,'Pesos Cartera K Sectorial'!$C$10:$L$10,'Pesos Cartera K Sectorial'!C54:L54) -> 0 | E25: 6.5 | G25: Corporativa | I25: =+C25 -> 0 | J25: =+H25/$G$6 -> 0 | K25: =+I25*$G$6 -> 0 | L25: =+K25-H25 -> 0
B26: High Yield | C26: =+LOOKUP($C$6,'Pesos Cartera K Sectorial'!$C$10:$L$10,'Pesos Cartera K Sectorial'!C55:L55) -> 0 | E26: 6 | G26: High Yield | H26: 0 | I26: =+C26 -> 0 | J26: =+H26/$G$6 -> 0 | K26: =+I26*$G$6 -> 0 | L26: =+K26-H26 -> 0
E27: =+(E21*C21+E22*C22+E23*C23+E25*C25+E26*C26)/C17 -> 9.136 | F27: Total Renta Fija | H27: =+H20+H25+H26 -> 500 | I27: =+I17 -> 0.1 | J27: =+H27/$G$6 -> 0.071428571 | K27: =+I27*$G$6 -> 700 | L27: =+K27-H27 -> 200
B29: Oro | C29: =+LOOKUP($C$6,'Pesos Cartera K Sectorial'!$C$10:$L$10,'Pesos Cartera K Sectorial'!C26:L26) -> 0.2 | G29: Oro | H29: =+I29*$G$6 -> 1400 | I29: =+C29 -> 0.2
G31: Activo | H31: Valor € Actual | I31: Peso Objetivo | J31: Peso Actual | K31: Valor € Objetivo | L31: Comprar/Vender
F32: Invesco Physical Gold A | G32: Oro | H32: 2500 | I32: =+I29 -> 0.2 | J32: =+H32/$G$6 -> 0.35714286 | K32: =+I32*$G$6 -> 1400 | L32: =+K32-H32 -> -1100
G34: TOTAL | H34: =+H32+H27+H13 -> 12000 | K34: =+K32+K27+K13 -> 7000 | L34: =+K34-H34 -> -5000
F40: Fondo Monetario que sirve para acumular liquidez
F41: ISIN | G41: Fondo | H41: Activo | I41: Valor € Actual | J41: TER
F42: FR0000447823 | G42: AXA Trésor Court Terme C | H42: Monetario | I42: 0 | J42: 0.0006

Sheet Control Cartera K Sectorial ETF
F2: Solo las celdas con este color se pueden modificar poniendo el capital actual en cada región o tipo de activo
G4: Capital Actual | H4: 9500 | J4: *El capital que suma todas las posiciones de la cartera
G5: Aportación | H5: 1000 | J5: * Aportación que quieres hacer a la cartera
B6: RIESGO | C6: 7 | G6: Capital Final | H6: =+H4+H5 -> 10500 | J6: * Capital final que quedará después de realizar la aportación
B9: Cartera | C9: Pesos | G9: Renta Variable | H9: =+I9*$H$6 -> 6825 | I9: =+C11 -> 0.65
B11: Renta Variable | C11: =+LOOKUP($C$6,'Pesos Cartera K Sectorial'!C10:L10,'Pesos Cartera K Sectorial'!C24:L24) -> 0.65 | G11: Región | H11: Valor € Actual | I11: Peso Objetivo | J11: Peso Actual | K11: Valor € Objetivo | L11: Comprar/Vender
B12: MSCI Staple | C12: =+LOOKUP($C$6,'Pesos Cartera K Sectorial'!$C$10:$L$10,'Pesos Cartera K Sectorial'!C40:L40) -> 0.1625 | F12: Xtrackers MSCI World Consumer Staples UCITS ETF 1C | G12: MSCI Staple | H12: 2500 | I12: =+C12 -> 0.1625 | J12: =+H12/$H$6 -> 0.23809524 | K12: =+I12*$H$6 -> 1706.25 | L12: =+K12-H12 -> -793.75
B13: MSCI Health Care | C13: =+LOOKUP($C$6,'Pesos Cartera K Sectorial'!$C$10:$L$10,'Pesos Cartera K Sectorial'!C41:L41) -> 0.1625 | F13: Xtrackers MSCI World Health Care UCITS ETF 1C | G13: MSCI Health Care | H13: 2000 | I13: =+C13 -> 0.1625 | J13: =+H13/$H$6 -> 0.19047619 | K13: =+I13*$H$6 -> 1706.25 | L13: =+K13-H13 -> -293.75
B14: MSCI Technology | C14: =+LOOKUP($C$6,'Pesos Cartera K Sectorial'!$C$10:$L$10,'Pesos Cartera K Sectorial'!C42:L42) -> 0.1625 | F14: Xtrackers MSCI World Information Technology UCITS ETF 1C | G14: MSCI Technology | H14: 1000 | I14: =+C14 -> 0.1625 | J14: =+H14/$H$6 -> 0.095238095 | K14: =+I14*$H$6 -> 1706.25 | L14: =+K14-H14 -> 706.25
B15: MSCI Energy | C15: =+LOOKUP($C$6,'Pesos Cartera K Sectorial'!$C$10:$L$10,'Pesos Cartera K Sectorial'!C43:L43) -> 0.08125 | F15: Xtrackers MSCI World Energy UCITS ETF 1C | G15: MSCI Energy | H15: 1000 | I15: =+C15 -> 0.08125 | J15: =+H15/$H$6 -> 0.095238095 | K15: =+I15*$H$6 -> 853.125 | L15: =+K15-H15 -> -146.875
B16: Global Real Estate | C16: =+LOOKUP($C$6,'Pesos Cartera K Sectorial'!$C$10:$L$10,'Pesos Cartera K Sectorial'!C44:L44) -> 0.08125 | F16: Amundi Index FTSE EPRA NAREIT Global UCITS ETF DR | G16: Global Real Estate | H16: 1000 | I16: =+C16 -> 0.08125 | J16: =+H16/$H$6 -> 0.095238095 | K16: =+I16*$H$6 -> 853.125 | L16: =+K16-H16 -> -146.875
F17: Total Renta Variable | H17: =SUM(H12:H16) -> 7500 | I17: =SUM(I12:I16) -> 0.65 | J17: =SUM(J12:J16) -> 0.71428571 | K17: =SUM(K12:K16) -> 6825 | L17: =SUM(L12:L16) -> -675
B19: Renta Fija | C19: =+LOOKUP($C$6,'Pesos Cartera K Sectorial'!$C$10:$L$10,'Pesos Cartera K Sectorial'!C25:L25) -> 0.15 | G19: Renta Fija | H19: =+I19*$H$6 -> 1575 | I19: =+C19 -> 0.15
G21: Tipo | H21: Valor € Actual | I21: Peso Objetivo | J21: Peso Actual | K21: Valor € Objetivo | L21: Comprar/Vender
B22: Gubernamental | C22: =+LOOKUP($C$6,'Pesos Cartera K Sectorial'!$C$10:$L$10,'Pesos Cartera K Sectorial'!C53:L53) -> 0.15 | E22: Duración Mod. | G22: Gubernamental | H22: =SUM(H23:H25) -> 0 | I22: =SUM(I23:I25) -> 0.15 | J22: =SUM(J23:J25) -> 0 | K22: =+I22*$H$6 -> 1575 | L22: =+K22-H22 -> 1575
B23: Largo Plazo | C23: 0.15 | E23: 10.25 | F23: Amundi Euro Government Bond 10-15Y UCITS ETF Acc | G23: Largo Plazo | I23: =+C23 -> 0.15 | J23: =+H23/$H$6 -> 0 | K23: =+I23*$H$6 -> 1575 | L23: =+K23-H23 -> 1575
B24: Medio Plazo | C24: 0 | E24: 6.84 | F24: Xtrackers II Global Government Bond UCITS ETF 1C EUR Hedged | G24: Medio Plazo | H24: 0 | I24: =+C24 -> 0 | J24: =+H24/$H$6 -> 0 | K24: =+I24*$H$6 -> 0 | L24: =+K24-H24 -> 0
B25: Corto Plazo | C25: 0 | E25: 1.88 | F25: iShares USD Treasury Bond 1-3yr UCITS ETF EUR Hedged (Acc) | G25: Corto Plazo | I25: =+C25 -> 0 | J25: =+H25/$H$6 -> 0 | K25: =+I25*$H$6 -> 0 | L25: =+K25-H25 -> 0
B27: Corporativa | C27: =+LOOKUP($C$6,'Pesos Cartera K Sectorial'!$C$10:$L$10,'Pesos Cartera K Sectorial'!C54:L54) -> 0 | E27: 4.44 | F27: Vanguard EUR Corporate Bond UCITS ETF Accumulating | G27: Corporativa | I27: =+C27 -> 0 | J27: =+H27/$H$6 -> 0 | K27: =+I27*$H$6 -> 0 | L27: =+K27-H27 -> 0
B28: High Yield | C28: =+LOOKUP($C$6,'Pesos Cartera K Sectorial'!$C$10:$L$10,'Pesos Cartera K Sectorial'!C55:L55) -> 0 | E28: 3.38 | F28: iShares EUR High Yield Corporate Bond ESG UCITS ETF EUR (Acc) | G28: High Yield | H28: 0 | I28: =+C28 -> 0 | J28: =+H28/$H$6 -> 0 | K28: =+I28*$H$6 -> 0 | L28: =+K28-H28 -> 0
E29: =+(E23*C23+E24*C24+E25*C25+E27*C27+E28*C28)/C19 -> 10.25 | F29: Total Renta Fija | H29: =+H22+H27+H28 -> 0 | I29: =+I19 -> 0.15 | J29: =+H29/$H$6 -> 0 | K29: =+I29*$H$6 -> 1575 | L29: =+K29-H29 -> 1575
B31: Oro | C31: =+LOOKUP($C$6,'Pesos Cartera K Sectorial'!$C$10:$L$10,'Pesos Cartera K Sectorial'!C26:L26) -> 0.2 | G31: Oro | H31: =+I31*$H$6 -> 2100 | I31: =+C31 -> 0.2
G33: Activo | H33: Valor € Actual | I33: Peso Objetivo | J33: Peso Actual | K33: Valor € Objetivo | L33: Comprar/Vender
F34: Invesco Physical Gold A | G34: Oro | H34: 2000 | I34: =+I31 -> 0.2 | J34: =+H34/$H$6 -> 0.19047619 | K34: =+I34*$H$6 -> 2100 | L34: =+K34-H34 -> 100
G36: TOTAL | H36: =+H34+H29+H17 -> 9500 | K36: =+K34+K29+K17 -> 10500 | L36: =+K36-H36 -> 1000
F42: Fondo Monetario que sirve para acumular liquidez
F43: ISIN | G43: Fondo | H43: Activo | I43: Valor € Actual | J43: TER
F44: FR0000447823 | G44: AXA Trésor Court Terme C | H44: Monetario | I44: 0 | J44: 0.0006

Sheet Control Cartera K Sectorial v2 
F2: Solo las celdas con este color se pueden modificar poniendo el capital actual en cada región o tipo de activo
G4: Capital Actual | H4: 100000 | J4: *El capital que suma todas las posiciones de la cartera
G5: Aportación | H5: 0 | J5: * Aportación que quieres hacer a la cartera
B6: RIESGO | C6: 10 | G6: Capital Final | H6: =+H4+H5 -> 100000 | J6: * Capital final que quedará después de realizar la aportación
B9: Cartera | C9: Pesos | G9: Renta Variable | H9: =+I9*$H$6 -> 80000 | I9: =+C11 -> 0.8
B11: Renta Variable | C11: =+LOOKUP($C$6,'Pesos Cartera K Sectorial'!C10:L10,'Pesos Cartera K Sectorial'!C24:L24) -> 0.8 | G11: Región | H11: Valor € Actual | I11: Peso Objetivo | J11: Peso Actual | K11: Valor € Objetivo | L11: Comprar/Vender
B12: MSCI Staple | C12: =+LOOKUP($C$6,'Pesos Cartera K Sectorial v2'!$C$10:$L$10,'Pesos Cartera K Sectorial v2'!$C$41:$L$41) -> 0.1 | F12: Xtrackers MSCI World Consumer Staples UCITS ETF 1C | G12: MSCI Staple | H12: 10000 | I12: =+C12 -> 0.1 | J12: =+H12/$H$6 -> 0.1 | K12: =+I12*$H$6 -> 10000 | L12: =+K12-H12 -> 0
B13: MSCI Utilities | C13: =+LOOKUP($C$6,'Pesos Cartera K Sectorial v2'!$C$10:$L$10,'Pesos Cartera K Sectorial v2'!$C$42:$L$42) -> 0.1 | F13: Xtrackers MSCI World Utilities UCITS ETF 1C | G13: MSCI Utilities | H13: 10000 | I13: =+C13 -> 0.1 | J13: =+H13/$H$6 -> 0.1 | K13: =+I13*$H$6 -> 10000 | L13: =+K13-H13 -> 0
B14: MSCI Health Care | C14: =+LOOKUP($C$6,'Pesos Cartera K Sectorial v2'!$C$10:$L$10,'Pesos Cartera K Sectorial v2'!$C$43:$L$43) -> 0.2 | F14: Xtrackers MSCI World Health Care UCITS ETF 1C | G14: MSCI Health Care | H14: 20000 | I14: =+C14 -> 0.2 | J14: =+H14/$H$6 -> 0.2 | K14: =+I14*$H$6 -> 20000 | L14: =+K14-H14 -> 0
B15: MSCI Technology | C15: =+LOOKUP($C$6,'Pesos Cartera K Sectorial v2'!$C$10:$L$10,'Pesos Cartera K Sectorial v2'!$C$44:$L$44) -> 0.2 | F15: Xtrackers MSCI World Information Technology UCITS ETF 1C | G15: MSCI Technology | H15: 20000 | I15: =+C15 -> 0.2 | J15: =+H15/$H$6 -> 0.2 | K15: =+I15*$H$6 -> 20000 | L15: =+K15-H15 -> 0
B16: MSCI Energy | C16: =+LOOKUP($C$6,'Pesos Cartera K Sectorial v2'!$C$10:$L$10,'Pesos Cartera K Sectorial v2'!$C$45:$L$45) -> 0.1 | F16: Xtrackers MSCI World Energy UCITS ETF 1C | G16: MSCI Energy | H16: 10000 | I16: =+C16 -> 0.1 | J16: =+H16/$H$6 -> 0.1 | K16: =+I16*$H$6 -> 10000 | L16: =+K16-H16 -> 0
B17: Global Real Estate | C17: =+LOOKUP($C$6,'Pesos Cartera K Sectorial v2'!$C$10:$L$10,'Pesos Cartera K Sectorial v2'!$C$46:$L$46) -> 0.1 | F17: Amundi Index FTSE EPRA NAREIT Global UCITS ETF DR | G17: Global Real Estate | H17: 10000 | I17: =+C17 -> 0.1 | J17: =+H17/$H$6 -> 0.1 | K17: =+I17*$H$6 -> 10000 | L17: =+K17-H17 -> 0
F18: Total Renta Variable | H18: =SUM(H12:H17) -> 80000 | I18: =SUM(I12:I17) -> 0.8 | J18: =SUM(J12:J17) -> 0.8 | K18: =SUM(K12:K17) -> 80000 | L18: =SUM(L12:L17) -> 0
B20: Renta Fija | C20: =+LOOKUP($C$6,'Pesos Cartera K Sectorial'!$C$10:$L$10,'Pesos Cartera K Sectorial'!C25:L25) -> 0 | G20: Renta Fija | H20: =+I20*$H$6 -> 0 | I20: =+C20 -> 0
G22: Tipo | H22: Valor € Actual | I22: Peso Objetivo | J22: Peso Actual | K22: Valor € Objetivo | L22: Comprar/Vender
B23: Gubernamental | C23: =+LOOKUP($C$6,'Pesos Cartera K Sectorial'!$C$10:$L$10,'Pesos Cartera K Sectorial'!C53:L53) -> 0 | E23: Duración Mod. | G23: Gubernamental | H23: =SUM(H24:H26) -> 0 | I23: =SUM(I24:I26) -> 0 | J23: =SUM(J24:J26) -> 0 | K23: =+I23*$H$6 -> 0 | L23: =+K23-H23 -> 0
B24: Largo Plazo | C24: 0 | E24: 10.25 | F24: Amundi Euro Government Bond 10-15Y UCITS ETF Acc | G24: Largo Plazo | I24: =+C24 -> 0 | J24: =+H24/$H$6 -> 0 | K24: =+I24*$H$6 -> 0 | L24: =+K24-H24 -> 0
B25: Medio Plazo | C25: 0 | E25: 6.84 | F25: Xtrackers II Global Government Bond UCITS ETF 1C EUR Hedged | G25: Medio Plazo | H25: 0 | I25: =+C25 -> 0 | J25: =+H25/$H$6 -> 0 | K25: =+I25*$H$6 -> 0 | L25: =+K25-H25 -> 0
B26: Corto Plazo | C26: 0 | E26: 1.88 | F26: iShares USD Treasury Bond 1-3yr UCITS ETF EUR Hedged (Acc) | G26: Corto Plazo | I26: =+C26 -> 0 | J26: =+H26/$H$6 -> 0 | K26: =+I26*$H$6 -> 0 | L26: =+K26-H26 -> 0
B28: Corporativa | C28: =+LOOKUP($C$6,'Pesos Cartera K Sectorial'!$C$10:$L$10,'Pesos Cartera K Sectorial'!C54:L54) -> 0 | E28: 4.44 | F28: Vanguard EUR Corporate Bond UCITS ETF Accumulating | G28: Corporativa | I28: =+C28 -> 0 | J28: =+H28/$H$6 -> 0 | K28: =+I28*$H$6 -> 0 | L28: =+K28-H28 -> 0
B29: High Yield | C29: =+LOOKUP($C$6,'Pesos Cartera K Sectorial'!$C$10:$L$10,'Pesos Cartera K Sectorial'!C55:L55) -> 0 | E29: 3.38 | F29: iShares EUR High Yield Corporate Bond ESG UCITS ETF EUR (Acc) | G29: High Yield | H29: 0 | I29: =+C29 -> 0 | J29: =+H29/$H$6 -> 0 | K29: =+I29*$H$6 -> 0 | L29: =+K29-H29 -> 0
E30: =+(E24*C24+E25*C25+E26*C26+E28*C28+E29*C29)/C20 -> #DIV/0! | F30: Total Renta Fija | H30: =+H23+H28+H29 -> 0 | I30: =+I20 -> 0 | J30: =+H30/$H$6 -> 0 | K30: =+I30*$H$6 -> 0 | L30: =+K30-H30 -> 0
B32: Oro | C32: =+LOOKUP($C$6,'Pesos Cartera K Sectorial'!$C$10:$L$10,'Pesos Cartera K Sectorial'!C26:L26) -> 0.2 | G32: Oro | H32: =+I32*$H$6 -> 20000 | I32: =+C32 -> 0.2
G34: Activo | H34: Valor € Actual | I34: Peso Objetivo | J34: Peso Actual | K34: Valor € Objetivo | L34: Comprar/Vender
F35: Invesco Physical Gold A | G35: Oro | H35: 2000 | I35: =+I32 -> 0.2 | J35: =+H35/$H$6 -> 0.02 | K35: =+I35*$H$6 -> 20000 | L35: =+K35-H35 -> 18000
G37: TOTAL | H37: =+H35+H30+H18 -> 82000 | K37: =+K35+K30+K18 -> 100000 | L37: =+K37-H37 -> 18000
F43: Fondo Monetario que sirve para acumular liquidez
F44: ISIN | G44: Fondo | H44: Activo | I44: Valor € Actual | J44: TER
F45: FR0000447823 | G45: AXA Trésor Court Terme C | H45: Monetario | I45: 0 | J45: 0.0006

Sheet Pesos Cartera K Geográfica
B4: RIESGO | C4: 1 | D4: 2 | E4: 3 | F4: 4 | G4: 5 | H4: 6 | I4: 7 | J4: 8 | K4: 9 | L4: 10
B5: Volatilidad Objetivo (1DE) | C5: 0.05 | D5: 0.055 | E5: 0.06 | F5: 0.07 | G5: 0.08 | H5: 0.09 | I5: 0.1 | J5: 0.11 | K5: 0.12 | L5: 0.13 | O5: Tabla de rentabilidad y volatilidad objetivo en función del perfil de riesgo con el tiempo mínimo y máximo estimado der recuperación
B6: Cisne Negro (-3*DE) | C6: =+C5*3 -> 0.15 | D6: =+D5*3 -> 0.165 | E6: =+E5*3 -> 0.18 | F6: =+F5*3 -> 0.21 | G6: =+G5*3 -> 0.24 | H6: =+H5*3 -> 0.27 | I6: =+I5*3 -> 0.3 | J6: =+J5*3 -> 0.33 | ... L6: =+L5*3 -> 0.39
B7: Rentabilidad para recuperar | C7: =1/(1-C6)-1 -> 0.17647059 | D7: =1/(1-D6)-1 -> 0.19760479 | E7: =1/(1-E6)-1 -> 0.2195122 | F7: =1/(1-F6)-1 -> 0.26582278 | G7: =1/(1-G6)-1 -> 0.31578947 | H7: =1/(1-H6)-1 -> 0.36986301 | I7: =1/(1-I6)-1 -> 0.42857143 | J7: =1/(1-J6)-1 -> 0.49253731 | ... L7: =1/(1-L6)-1 -> 0.63934426
B8: Rentabilidad estimada después de CN | C8: 0.05 | D8: =+D5 -> 0.055 | E8: =+E5 -> 0.06 | F8: =+F5 -> 0.07 | G8: =+G5 -> 0.08 | H8: =+H5 -> 0.09 | I8: =+I5 -> 0.1 | J8: =+J5 -> 0.11 | K8: =+K5 -> 0.12 | L8: =+L5 -> 0.13
B9: Años Para recupar | C9: =LN(1+C7)/LN(1+C8) -> 3.3309773 | D9: =LN(1+D7)/LN(1+D8) -> 3.3679673 | E9: =LN(1+E7)/LN(1+E8) -> 3.4057775 | F9: =LN(1+F7)/LN(1+F8) -> 3.4839941 | G9: =LN(1+G7)/LN(1+G8) -> 3.5659191 | H9: =LN(1+H7)/LN(1+H8) -> 3.6518816 | I9: =LN(1+I7)/LN(1+I8) -> 3.7422544 | J9: =LN(1+J7)/LN(1+J8) -> 3.8374617 | ... L9: =LN(1+L7)/LN(1+L8) -> 4.0443945
B11: Rentabilidad esperada Indexa Capital | C11: 0.03 | D11: 0.033 | E11: 0.036 | F11: 0.038 | G11: 0.041 | H11: 0.044 | I11: 0.046 | J11: 0.049 | K11: 0.052 | L11: 0.056
B12: Años Para recupar | C12: =LN(1+C7)/LN(1+C11) -> 5.4981568 | D12: =LN(1+D7)/LN(1+D11) -> 5.554024 | E12: =LN(1+E7)/LN(1+E11) -> 5.6111667 | F12: =LN(1+F7)/LN(1+F11) -> 6.3203479 | G12: =LN(1+G7)/LN(1+G11) -> 6.8298811 | H12: =LN(1+H7)/LN(1+H11) -> 7.3087431 | I12: =LN(1+I7)/LN(1+I11) -> 7.9308039 | J12: =LN(1+J7)/LN(1+J11) -> 8.3716539 | ... L12: =LN(1+L7)/LN(1+L11) -> 9.0716239
B17: Pesos por Clase
B18: Renta Variable | C18: 0.1 | D18: 0.15 | E18: 0.25 | F18: 0.35 | G18: 0.45 | H18: 0.55 | I18: 0.65 | J18: 0.7 | K18: 0.74 | L18: 0.8 | O18: Tabla con distribución de pesos por clase de activo en función de su perfil de riesgo
B19: Renta Fija | C19: 0.75 | D19: 0.7 | E19: 0.6 | F19: 0.5 | G19: 0.35 | H19: 0.25 | I19: 0.15 | J19: 0.1 | K19: 0.06 | L19: 0
B20: Oro | C20: 0.15 | D20: 0.15 | E20: 0.15 | F20: 0.15 | G20: 0.2 | H20: 0.2 | I20: 0.2 | J20: 0.2 | K20: 0.2 | L20: 0.2
B21: TOTAL | C21: =SUM(C18:C20) -> 1 | D21: =SUM(D18:D20) -> 1 | E21: =SUM(E18:E20) -> 1 | F21: =SUM(F18:F20) -> 1 | G21: =SUM(G18:G20) -> 1 | H21: =SUM(H18:H20) -> 1 | I21: =SUM(I18:I20) -> 1 | J21: =SUM(J18:J20) -> 1 | ... L21: =SUM(L18:L20) -> 1
B25: Renta Variable MSCI ACWI | E25: Tabla con distribución de pesos por área geográfica según MSCI ACWI
B26: Global | C26: 0.93
B27: Emergente | C27: 0.07
B28: TOTAL | C28: =SUM(C26:C27) -> 1
B30: Global | C30: =+$C$26*C18 -> 0.093 | D30: =+$C$26*D18 -> 0.1395 | E30: =+$C$26*E18 -> 0.2325 | F30: =+$C$26*F18 -> 0.3255 | G30: =+$C$26*G18 -> 0.4185 | H30: =+$C$26*H18 -> 0.5115 | I30: =+$C$26*I18 -> 0.6045 | J30: =+$C$26*J18 -> 0.651 | ... L30: =+$C$26*L18 -> 0.744 | O30: Tabla con distribución de peso relativos por área geográfica según el MSCI ACWI por perfil de riesgo.
B31: Emergente | C31: =+$C$27*C18 -> 0.007 | D31: =+$C$27*D18 -> 0.0105 | E31: =+$C$27*E18 -> 0.0175 | F31: =+$C$27*F18 -> 0.0245 | G31: =+$C$27*G18 -> 0.0315 | H31: =+$C$27*H18 -> 0.0385 | I31: =+$C$27*I18 -> 0.0455 | J31: =+$C$27*J18 -> 0.049 | ... L31: =+$C$27*L18 -> 0.056
B32: Renta Variable | C32: =SUM(C30:C31) -> 0.1 | D32: =SUM(D30:D31) -> 0.15 | E32: =SUM(E30:E31) -> 0.25 | F32: =SUM(F30:F31) -> 0.35 | G32: =SUM(G30:G31) -> 0.45 | H32: =SUM(H30:H31) -> 0.55 | I32: =SUM(I30:I31) -> 0.65 | J32: =SUM(J30:J31) -> 0.7 | ... L32: =SUM(L30:L31) -> 0.8
B37: Renta Fija Peso Relativo Cartera | C37: =+C38+C39+C40 -> 0.75 | D37: =+D38+D39+D40 -> 0.7 | E37: =+E38+E39+E40 -> 0.6 | F37: =+F38+F39+F40 -> 0.5 | G37: =+G38+G39+G40 -> 0.35 | H37: =+H38+H39+H40 -> 0.25 | I37: =+I38+I39+I40 -> 0.15 | J37: =+J38+J39+J40 -> 0.1 | ... L37: =+L38+L39+L40 -> 0 | O37: Tabla con distribución de pesos por tipo de renta fija por perfil de riesgo.
B38: Gubernamental | C38: 0.45 | D38: 0.42 | E38: 0.36 | F38: 0.35 | G38: 0.28 | H38: 0.25 | I38: 0.15 | J38: 0.1 | K38: 0.05 | L38: 0
B39: Corporativa | C39: 0.23 | D39: 0.18 | E39: 0.15 | F39: 0.1 | G39: 0.05 | H39: 0 | I39: 0 | J39: 0 | K39: 0 | L39: 0
B40: High Yield | C40: 0.07 | D40: 0.1 | E40: 0.09 | F40: 0.05 | G40: 0.02 | H40: 0 | I40: 0 | J40: 0 | K40: 0 | L40: 0

Sheet Pesos Cartera K Sectorial
B10: RIESGO | C10: 1 | D10: 2 | E10: 3 | F10: 4 | G10: 5 | H10: 6 | I10: 7 | J10: 8 | K10: 9 | L10: 10
B11: Volatilidad Objetivo (1DE) | C11: 0.05 | D11: 0.055 | E11: 0.06 | F11: 0.07 | G11: 0.08 | H11: 0.09 | I11: 0.1 | J11: 0.11 | K11: 0.12 | L11: 0.13 | O11: Tabla de rentabilidad y volatilidad objetivo en función del perfil de riesgo con el tiempo mínimo y máximo estimado der recuperación
B12: Cisne Negro | C12: =+C11*3 -> 0.15 | D12: =+D11*3 -> 0.165 | E12: =+E11*3 -> 0.18 | F12: =+F11*3 -> 0.21 | G12: =+G11*3 -> 0.24 | H12: =+H11*3 -> 0.27 | I12: =+I11*3 -> 0.3 | J12: =+J11*3 -> 0.33 | ... L12: =+L11*3 -> 0.39
B13: Rentabilidad para recuperar | C13: =1/(1-C12)-1 -> 0.17647059 | D13: =1/(1-D12)-1 -> 0.19760479 | E13: =1/(1-E12)-1 -> 0.2195122 | F13: =1/(1-F12)-1 -> 0.26582278 | G13: =1/(1-G12)-1 -> 0.31578947 | H13: =1/(1-H12)-1 -> 0.36986301 | I13: =1/(1-I12)-1 -> 0.42857143 | J13: =1/(1-J12)-1 -> 0.49253731 | ... L13: =1/(1-L12)-1 -> 0.63934426
B14: Rentabilidad estimada después de CN | C14: =+C11 -> 0.05 | D14: =+D11 -> 0.055 | E14: =+E11 -> 0.06 | F14: =+F11 -> 0.07 | G14: =+G11 -> 0.08 | H14: =+H11 -> 0.09 | I14: =+I11 -> 0.1 | J14: =+J11 -> 0.11 | ... L14: =+L11 -> 0.13
B15: Años Para recupar | C15: =LN(1+C13)/LN(1+C14) -> 3.3309773 | D15: =LN(1+D13)/LN(1+D14) -> 3.3679673 | E15: =LN(1+E13)/LN(1+E14) -> 3.4057775 | F15: =LN(1+F13)/LN(1+F14) -> 3.4839941 | G15: =LN(1+G13)/LN(1+G14) -> 3.5659191 | H15: =LN(1+H13)/LN(1+H14) -> 3.6518816 | I15: =LN(1+I13)/LN(1+I14) -> 3.7422544 | J15: =LN(1+J13)/LN(1+J14) -> 3.8374617 | ... L15: =LN(1+L13)/LN(1+L14) -> 4.0443945
B17: Rentabilidad esperada Indexa Capital | C17: 0.03 | D17: 0.033 | E17: 0.036 | F17: 0.038 | G17: 0.041 | H17: 0.044 | I17: 0.046 | J17: 0.049 | K17: 0.052 | L17: 0.056
B18: Años Para recupar | C18: =LN(1+C13)/LN(1+C17) -> 5.4981568 | D18: =LN(1+D13)/LN(1+D17) -> 5.554024 | E18: =LN(1+E13)/LN(1+E17) -> 5.6111667 | F18: =LN(1+F13)/LN(1+F17) -> 6.3203479 | G18: =LN(1+G13)/LN(1+G17) -> 6.8298811 | H18: =LN(1+H13)/LN(1+H17) -> 7.3087431 | I18: =LN(1+I13)/LN(1+I17) -> 7.9308039 | J18: =LN(1+J13)/LN(1+J17) -> 8.3716539 | ... L18: =LN(1+L13)/LN(1+L17) -> 9.0716239
B23: Pesos por Clase | O23: Tabla con distribución de pesos por clase de activo en función de su perfil de riesgo
B24: Renta Variable | C24: 0.1 | D24: 0.15 | E24: 0.25 | F24: 0.35 | G24: 0.45 | H24: 0.55 | I24: 0.65 | J24: 0.7 | K24: 0.75 | L24: 0.8
B25: Renta Fija | C25: 0.75 | D25: 0.7 | E25: 0.6 | F25: 0.5 | G25: 0.35 | H25: 0.25 | I25: 0.15 | J25: 0.1 | K25: 0.05 | L25: 0
B26: Oro | C26: 0.15 | D26: 0.15 | E26: 0.15 | F26: 0.15 | G26: 0.2 | H26: 0.2 | I26: 0.2 | J26: 0.2 | K26: 0.2 | L26: 0.2
B27: TOTAL | C27: =SUM(C24:C26) -> 1 | D27: =SUM(D24:D26) -> 1 | E27: =SUM(E24:E26) -> 1 | F27: =SUM(F24:F26) -> 1 | G27: =SUM(G24:G26) -> 1 | H27: =SUM(H24:H26) -> 1 | I27: =SUM(I24:I26) -> 1 | J27: =SUM(J24:J26) -> 1 | ... L27: =SUM(L24:L26) -> 1
B31: Renta Variable | E31: Tabla de distribución de peso por sector
B32: MSCI Staple | C32: 0.25
B33: MSCI Health Care | C33: 0.25
B34: MSCI Technology | C34: 0.25
B35: MSCI Energy | C35: 0.125
B36: Global Real Estate | C36: 0.125
B37: TOTAL | C37: =SUM(C32:C36) -> 1
B40: MSCI Staple | C40: =+$C$32*C24 -> 0.025 | D40: =+$C$32*D24 -> 0.0375 | E40: =+$C$32*E24 -> 0.0625 | F40: =+$C$32*F24 -> 0.0875 | G40: =+$C$32*G24 -> 0.1125 | H40: =+$C$32*H24 -> 0.1375 | I40: =+$C$32*I24 -> 0.1625 | J40: =+$C$32*J24 -> 0.175 | ... L40: =+$C$32*L24 -> 0.2 | O40: Tabla con distribución de peso relativos por sector en función del perfil de riesgo.
B41: MSCI Health Care | C41: =+$C$33*C24 -> 0.025 | D41: =+$C$33*D24 -> 0.0375 | E41: =+$C$33*E24 -> 0.0625 | F41: =+$C$33*F24 -> 0.0875 | G41: =+$C$33*G24 -> 0.1125 | H41: =+$C$33*H24 -> 0.1375 | I41: =+$C$33*I24 -> 0.1625 | J41: =+$C$33*J24 -> 0.175 | ... L41: =+$C$33*L24 -> 0.2
B42: MSCI Technology | C42: =+$C$34*C24 -> 0.025 | D42: =+$C$34*D24 -> 0.0375 | E42: =+$C$34*E24 -> 0.0625 | F42: =+$C$34*F24 -> 0.0875 | G42: =+$C$34*G24 -> 0.1125 | H42: =+$C$34*H24 -> 0.1375 | I42: =+$C$34*I24 -> 0.1625 | J42: =+$C$34*J24 -> 0.175 | ... L42: =+$C$34*L24 -> 0.2
B43: MSCI Energy | C43: =+$C$35*C24 -> 0.0125 | D43: =+$C$35*D24 -> 0.01875 | E43: =+$C$35*E24 -> 0.03125 | F43: =+$C$35*F24 -> 0.04375 | G43: =+$C$35*G24 -> 0.05625 | H43: =+$C$35*H24 -> 0.06875 | I43: =+$C$35*I24 -> 0.08125 | J43: =+$C$35*J24 -> 0.0875 | ... L43: =+$C$35*L24 -> 0.1
B44: Global Real Estate | C44: =+$C$36*C24 -> 0.0125 | D44: =+$C$36*D24 -> 0.01875 | E44: =+$C$36*E24 -> 0.03125 | F44: =+$C$36*F24 -> 0.04375 | G44: =+$C$36*G24 -> 0.05625 | H44: =+$C$36*H24 -> 0.06875 | I44: =+$C$36*I24 -> 0.08125 | J44: =+$C$36*J24 -> 0.0875 | ... L44: =+$C$36*L24 -> 0.1
B45: Renta Variable | C45: =SUM(C40:C44) -> 0.1 | D45: =SUM(D40:D44) -> 0.15 | E45: =SUM(E40:E44) -> 0.25 | F45: =SUM(F40:F44) -> 0.35 | G45: =SUM(G40:G44) -> 0.45 | H45: =SUM(H40:H44) -> 0.55 | I45: =SUM(I40:I44) -> 0.65 | J45: =SUM(J40:J44) -> 0.7 | ... L45: =SUM(L40:L44) -> 0.8
B52: Renta Fija Peso Relativo Cartera | C52: =+C53+C54+C55 -> 0.75 | D52: =+D53+D54+D55 -> 0.7 | E52: =+E53+E54+E55 -> 0.6 | F52: =+F53+F54+F55 -> 0.5 | G52: =+G53+G54+G55 -> 0.35 | H52: =+H53+H54+H55 -> 0.25 | I52: =+I53+I54+I55 -> 0.15 | J52: =+J53+J54+J55 -> 0.1 | ... L52: =+L53+L54+L55 -> 0 | O52: Tabla con distribución de pesos por tipo de renta fija por perfil de riesgo.
B53: Gubernamental | C53: 0.45 | D53: 0.42 | E53: 0.36 | F53: 0.35 | G53: 0.28 | H53: 0.25 | I53: 0.15 | J53: 0.1 | K53: 0.05 | L53: 0
B54: Corporativa | C54: 0.23 | D54: 0.18 | E54: 0.15 | F54: 0.1 | G54: 0.05 | H54: 0 | I54: 0 | J54: 0 | K54: 0 | L54: 0
B55: High Yield | C55: 0.07 | D55: 0.1 | E55: 0.09 | F55: 0.05 | G55: 0.02 | H55: 0 | I55: 0 | J55: 0 | K55: 0 | L55: 0

Sheet Pesos Cartera K Sectorial v2
B10: RIESGO | C10: 1 | D10: 2 | E10: 3 | F10: 4 | G10: 5 | H10: 6 | I10: 7 | J10: 8 | K10: 9 | L10: 10
B11: Volatilidad Objetivo (1DE) | C11: 0.05 | D11: 0.055 | E11: 0.06 | F11: 0.07 | G11: 0.08 | H11: 0.09 | I11: 0.1 | J11: 0.11 | K11: 0.12 | L11: 0.13 | O11: Tabla de rentabilidad y volatilidad objetivo en función del perfil de riesgo con el tiempo mínimo y máximo estimado der recuperación
B12: Cisne Negro | C12: =+C11*3 -> 0.15 | D12: =+D11*3 -> 0.165 | E12: =+E11*3 -> 0.18 | F12: =+F11*3 -> 0.21 | G12: =+G11*3 -> 0.24 | H12: =+H11*3 -> 0.27 | I12: =+I11*3 -> 0.3 | J12: =+J11*3 -> 0.33 | ... L12: =+L11*3 -> 0.39
B13: Rentabilidad para recuperar | C13: =1/(1-C12)-1 -> 0.17647059 | D13: =1/(1-D12)-1 -> 0.19760479 | E13: =1/(1-E12)-1 -> 0.2195122 | F13: =1/(1-F12)-1 -> 0.26582278 | G13: =1/(1-G12)-1 -> 0.31578947 | H13: =1/(1-H12)-1 -> 0.36986301 | I13: =1/(1-I12)-1 -> 0.42857143 | J13: =1/(1-J12)-1 -> 0.49253731 | ... L13: =1/(1-L12)-1 -> 0.63934426
B14: Rentabilidad estimada después de CN | C14: =+C11 -> 0.05 | D14: =+D11 -> 0.055 | E14: =+E11 -> 0.06 | F14: =+F11 -> 0.07 | G14: =+G11 -> 0.08 | H14: =+H11 -> 0.09 | I14: =+I11 -> 0.1 | J14: =+J11 -> 0.11 | ... L14: =+L11 -> 0.13
B15: Años Para recupar | C15: =LN(1+C13)/LN(1+C14) -> 3.3309773 | D15: =LN(1+D13)/LN(1+D14) -> 3.3679673 | E15: =LN(1+E13)/LN(1+E14) -> 3.4057775 | F15: =LN(1+F13)/LN(1+F14) -> 3.4839941 | G15: =LN(1+G13)/LN(1+G14) -> 3.5659191 | H15: =LN(1+H13)/LN(1+H14) -> 3.6518816 | I15: =LN(1+I13)/LN(1+I14) -> 3.7422544 | J15: =LN(1+J13)/LN(1+J14) -> 3.8374617 | ... L15: =LN(1+L13)/LN(1+L14) -> 4.0443945
B17: Rentabilidad esperada Indexa Capital | C17: 0.03 | D17: 0.033 | E17: 0.036 | F17: 0.038 | G17: 0.041 | H17: 0.044 | I17: 0.046 | J17: 0.049 | K17: 0.052 | L17: 0.056
B18: Años Para recupar | C18: =LN(1+C13)/LN(1+C17) -> 5.4981568 | D18: =LN(1+D13)/LN(1+D17) -> 5.554024 | E18: =LN(1+E13)/LN(1+E17) -> 5.6111667 | F18: =LN(1+F13)/LN(1+F17) -> 6.3203479 | G18: =LN(1+G13)/LN(1+G17) -> 6.8298811 | H18: =LN(1+H13)/LN(1+H17) -> 7.3087431 | I18: =LN(1+I13)/LN(1+I17) -> 7.9308039 | J18: =LN(1+J13)/LN(1+J17) -> 8.3716539 | ... L18: =LN(1+L13)/LN(1+L17) -> 9.0716239
B23: Pesos por Clase | O23: Tabla con distribución de pesos por clase de activo en función de su perfil de riesgo
B24: Renta Variable | C24: 0.1 | D24: 0.15 | E24: 0.25 | F24: 0.35 | G24: 0.45 | H24: 0.55 | I24: 0.65 | J24: 0.7 | K24: 0.75 | L24: 0.8
B25: Renta Fija | C25: 0.75 | D25: 0.7 | E25: 0.6 | F25: 0.5 | G25: 0.35 | H25: 0.25 | I25: 0.15 | J25: 0.1 | K25: 0.05 | L25: 0
B26: Oro | C26: 0.15 | D26: 0.15 | E26: 0.15 | F26: 0.15 | G26: 0.2 | H26: 0.2 | I26: 0.2 | J26: 0.2 | K26: 0.2 | L26: 0.2
B27: TOTAL | C27: =SUM(C24:C26) -> 1 | D27: =SUM(D24:D26) -> 1 | E27: =SUM(E24:E26) -> 1 | F27: =SUM(F24:F26) -> 1 | G27: =SUM(G24:G26) -> 1 | H27: =SUM(H24:H26) -> 1 | I27: =SUM(I24:I26) -> 1 | J27: =SUM(J24:J26) -> 1 | ... L27: =SUM(L24:L26) -> 1
B31: Renta Variable | E31: Tabla de distribución de peso por sector
B32: MSCI Staple | C32: 0.125
B33: MSCI Utilities | C33: 0.125
B34: MSCI Health Care | C34: 0.25
B35: MSCI Technology | C35: 0.25
B36: MSCI Energy | C36: 0.125
B37: Global Real Estate | C37: 0.125
B38: TOTAL | C38: =SUM(C32:C37) -> 1
B41: MSCI Staple | C41: =+$C$32*C24 -> 0.0125 | D41: =+$C$32*D24 -> 0.01875 | E41: =+$C$32*E24 -> 0.03125 | F41: =+$C$32*F24 -> 0.04375 | G41: =+$C$32*G24 -> 0.05625 | H41: =+$C$32*H24 -> 0.06875 | I41: =+$C$32*I24 -> 0.08125 | J41: =+$C$32*J24 -> 0.0875 | ... L41: =+$C$32*L24 -> 0.1 | O41: Tabla con distribución de peso relativos por sector en función del perfil de riesgo.
B42: MSCI Utilities | C42: =+$C$33*C24 -> 0.0125 | D42: =+$C$33*D24 -> 0.01875 | E42: =+$C$33*E24 -> 0.03125 | F42: =+$C$33*F24 -> 0.04375 | G42: =+$C$33*G24 -> 0.05625 | H42: =+$C$33*H24 -> 0.06875 | I42: =+$C$33*I24 -> 0.08125 | J42: =+$C$33*J24 -> 0.0875 | ... L42: =+$C$33*L24 -> 0.1
B43: MSCI Health Care | C43: =+$C$34*C24 -> 0.025 | D43: =+$C$34*D24 -> 0.0375 | E43: =+$C$34*E24 -> 0.0625 | F43: =+$C$34*F24 -> 0.0875 | G43: =+$C$34*G24 -> 0.1125 | H43: =+$C$34*H24 -> 0.1375 | I43: =+$C$34*I24 -> 0.1625 | J43: =+$C$34*J24 -> 0.175 | ... L43: =+$C$34*L24 -> 0.2
B44: MSCI Technology | C44: =+$C$35*C24 -> 0.025 | D44: =+$C$35*D24 -> 0.0375 | E44: =+$C$35*E24 -> 0.0625 | F44: =+$C$35*F24 -> 0.0875 | G44: =+$C$35*G24 -> 0.1125 | H44: =+$C$35*H24 -> 0.1375 | I44: =+$C$35*I24 -> 0.1625 | J44: =+$C$35*J24 -> 0.175 | ... L44: =+$C$35*L24 -> 0.2
B45: MSCI Energy | C45: =+$C$36*C24 -> 0.0125 | D45: =+$C$36*D24 -> 0.01875 | E45: =+$C$36*E24 -> 0.03125 | F45: =+$C$36*F24 -> 0.04375 | G45: =+$C$36*G24 -> 0.05625 | H45: =+$C$36*H24 -> 0.06875 | I45: =+$C$36*I24 -> 0.08125 | J45: =+$C$36*J24 -> 0.0875 | ... L45: =+$C$36*L24 -> 0.1
B46: Global Real Estate | C46: =+$C$37*C24 -> 0.0125 | D46: =+$C$37*D24 -> 0.01875 | E46: =+$C$37*E24 -> 0.03125 | F46: =+$C$37*F24 -> 0.04375 | G46: =+$C$37*G24 -> 0.05625 | H46: =+$C$37*H24 -> 0.06875 | I46: =+$C$37*I24 -> 0.08125 | J46: =+$C$37*J24 -> 0.0875 | ... L46: =+$C$37*L24 -> 0.1
B47: Renta Variable | C47: =SUM(C41:C46) -> 0.1 | D47: =SUM(D41:D46) -> 0.15 | E47: =SUM(E41:E46) -> 0.25 | F47: =SUM(F41:F46) -> 0.35 | G47: =SUM(G41:G46) -> 0.45 | H47: =SUM(H41:H46) -> 0.55 | I47: =SUM(I41:I46) -> 0.65 | J47: =SUM(J41:J46) -> 0.7 | ... L47: =SUM(L41:L46) -> 0.8
B54: Renta Fija Peso Relativo Cartera | C54: =+C55+C56+C57 -> 0.75 | D54: =+D55+D56+D57 -> 0.7 | E54: =+E55+E56+E57 -> 0.6 | F54: =+F55+F56+F57 -> 0.5 | G54: =+G55+G56+G57 -> 0.35 | H54: =+H55+H56+H57 -> 0.25 | I54: =+I55+I56+I57 -> 0.15 | J54: =+J55+J56+J57 -> 0.1 | ... L54: =+L55+L56+L57 -> 0 | O54: Tabla con distribución de pesos por tipo de renta fija por perfil de riesgo.
B55: Gubernamental | C55: 0.45 | D55: 0.42 | E55: 0.36 | F55: 0.35 | G55: 0.28 | H55: 0.25 | I55: 0.15 | J55: 0.1 | K55: 0.05 | L55: 0
B56: Corporativa | C56: 0.23 | D56: 0.18 | E56: 0.15 | F56: 0.1 | G56: 0.05 | H56: 0 | I56: 0 | J56: 0 | K56: 0 | L56: 0
B57: High Yield | C57: 0.07 | D57: 0.1 | E57: 0.09 | F57: 0.05 | G57: 0.02 | H57: 0 | I57: 0 | J57: 0 | K57: 0 | L57: 0
